Traceback (most recent call last):
  File "python/figonecool4.py", line 85, in <module>
    storeData()
  File "python/figonecool4.py", line 64, in storeData
    processBranchData(bmpnum,datapath)
  File "python/figonecool4.py", line 29, in processBranchData
    processData(datapath)
  File "python/figonecool4.py", line 23, in processData
    img = Image(filename = datapath)
  File "/usr/local/lib/python2.7/dist-packages/wand/image.py", line 2400, in __init__
    self.read(filename=filename, resolution=resolution)
  File "/usr/local/lib/python2.7/dist-packages/wand/image.py", line 2457, in read
    self.raise_exception()
  File "/usr/local/lib/python2.7/dist-packages/wand/resource.py", line 222, in raise_exception
    raise e
wand.exceptions.BlobError: unable to open image `/home/joseph/ether/test/book.bmp': No such file or directory @ error/blob.c/OpenBlob/2638
